Workbook
Name Slicer_Markets: #N/A
Name Slicer_Months: #N/A
Name Slicer_SD: #N/A
Name Slicer_SD1: #N/A
Name Slicer_SD2: #N/A
Name Slicer_TM: #N/A
Name Slicer_TM_Name1: #N/A
Name Slicer_TM1: #N/A
Name Slicer_TM2: #N/A
Name Slicer_VP: #N/A
Name Slicer_VP1: #N/A
Name Slicer_VP11: #N/A
Name Slicer_Week_No: #N/A

Sheet Cover

Sheet Summary
B1: Budgeted vs Actual Hours 08 - 13 Apr 2026 | I1: Pay Period Wise OT Hours | P1: Week Wise OT Hours
B3: VP/TM | C3: Weekly Budgeted HRS as of 08 - 14 Apr | D3: Regular Hours as of 08 - 13 Apr 2026 | E3: Overtime Hours as of 08 - 13 Apr 2026 | F3: Other Hours as of 08 - 13 Apr 2026 | G3: Total Hours as of 08 - 13 Apr 2026 | I3: VP/TM | J3: Pay Period 01 - 14 Apr | K3: Pay Period 18 March - 31 March | L3: Pay Period 04 March - 17 March | M3: Pay Period 18 Feb to 03 Mar | P3: VP/TM | Q3: 08 - 14 Apr 2026 | R3: 01 - 07 Apr 2026 | S3: 25 - 31 Mar 2026 | T3: 18-24 Mar 2026
B4: Anthony Galichet | C4: 10061.6 | D4: 7112.92 | E4: 39.4 | F4: 0 | G4: 7152.32 | I4: Anthony Galichet | J4: 140.29 | K4: 192.84 | L4: 217.87 | M4: 244.31 | P4: Anthony Galichet | Q4: 39.4 | R4: 100.89 | S4: 99.72 | T4: 93.12
B5: Austin TM | C5: 472.1 | D5: 355.76 | E5: 4.88 | F5: 0 | G5: 360.64 | I5: Austin TM | J5: 11.81 | K5: 29.7 | L5: 27.05 | M5: 24.91 | P5: Austin TM | Q5: 4.88 | R5: 6.93 | S5: 17.04 | T5: 12.66
B6: Carlos Ayala-Level Up | C6: 1334 | D6: 899.51 | E6: 0.87 | F6: 0 | G6: 900.38 | I6: Carlos Ayala-Level Up | J6: 2.54 | K6: 42.1 | L6: 28.76 | M6: 37.7 | P6: Carlos Ayala-Level Up | Q6: 0.87 | R6: 1.67 | S6: 21.19 | T6: 20.91
B7: Colorado Market - No TM | C7: 742.5 | D7: 556.6 | E7: 0 | F7: 0 | G7: 556.6 | I7: Colorado Market - No TM | J7: 13.31 | K7: 17.24 | L7: 24.75 | M7: 66.54 | P7: Colorado Market - No TM | Q7: 0 | R7: 13.31 | S7: 7.74 | T7: 9.5
B8: Isreal Gomez- Level Up | C8: 797 | D8: 424.49 | E8: 22.17 | F8: 0 | G8: 446.66 | I8: Isreal Gomez- Level Up | J8: 58.71 | K8: 61.23 | L8: 66.71 | M8: 31.5 | P8: Isreal Gomez- Level Up | Q8: 22.17 | R8: 36.54 | S8: 23.84 | T8: 37.39
B9: Jayme Roraff | C9: 1474.5 | D9: 897.22 | E9: 0 | F9: 0 | G9: 897.22 | I9: Jayme Roraff | J9: 22.41 | K9: 0.76 | L9: 13.09 | M9: 38.08 | P9: Jayme Roraff | Q9: 0 | R9: 22.41 | S9: 0.58 | T9: 0.18
B10: North Carolina Market - No TM | C10: 543 | D10: 420.13 | E10: 0 | F10: 0 | G10: 420.13 | I10: North Carolina Market - No TM | J10: 0.58 | K10: 0.71 | L10: 0.7 | M10: 0.07 | P10: North Carolina Market - No TM | Q10: 0 | R10: 0.58 | S10: 0.71 | T10: 0
B11: Suhail Ishaq | C11: 1617 | D11: 1085.27 | E11: 2.31 | F11: 0 | G11: 1087.58 | I11: Suhail Ishaq | J11: 9.65 | K11: 26.04 | L11: 28.67 | M11: 35.36 | P11: Suhail Ishaq | Q11: 2.31 | R11: 7.34 | S11: 17.17 | T11: 8.87
B12: Susu Leong | C12: 1244 | D12: 972.16 | E12: 9 | F12: 0 | G12: 981.16 | I12: Susu Leong | J12: 21.11 | K12: 5.26 | L12: 27.07 | M12: 10.15 | P12: Susu Leong | Q12: 9 | R12: 12.11 | S12: 1.67 | T12: 3.59
B13: Veronica Ramos | C13: 1837.5 | D13: 1501.78 | E13: 0.17 | F13: 0 | G13: 1501.95 | I13: Veronica Ramos | J13: 0.17 | K13: 9.8 | L13: 1.07 | M13: 0 | P13: Veronica Ramos | Q13: 0.17 | R13: 0 | S13: 9.78 | T13: 0.02
B14: Grand Total | C14: 10061.6 | D14: 7112.92 | E14: 39.4 | F14: 0 | G14: 7152.32 | I14: Grand Total | J14: 140.29 | K14: 192.84 | L14: 217.87 | M14: 244.31 | P14: Grand Total | Q14: 39.4 | R14: 100.89 | S14: 99.72 | T14: 93.12

Sheet Overtime 01 - 07 Apr
L1: Total | M1: =SUBTOTAL(9,M3:M1048576) -> 100.89
A2: VP | B2: SD | C2: TM | D2: HRBP | E2: SEL | F2: Market | G2: Store | H2: UID | I2: Date | J2: Paycom ID | K2: Name | L2: Role | M2: Hours
A3: =INDEX('MO Store'!D:D,MATCH('Overtime 01 - 07 Apr'!$H3,'MO Store'!$A:$A,0)) -> Anthony Galichet | B3: =INDEX('MO Store'!F:F,MATCH('Overtime 01 - 07 Apr'!$H3,'MO Store'!$A:$A,0)) -> Romio Hamdar | C3: =IFERROR(INDEX('MO Store'!G:G,MATCH('Overtime 01 - 07 Apr'!$H3,'MO Store'!$A:$A,0)),"") -> Suhail Ishaq | D3: =INDEX('MO Store'!E:E,MATCH('Overtime 01 - 07 Apr'!$H3,'MO Store'!$A:$A,0)) -> Brittanie Braggs | E3: =IFERROR(INDEX('MO Store'!H:H,MATCH('Overtime 01 - 07 Apr'!$H3,'MO Store'!$A:$A,0)),"") -> No SEL | F3: =INDEX('MO Store'!B:B,MATCH('Overtime 01 - 07 Apr'!$H3,'MO Store'!$A:$A,0)) -> Houston North East | G3: =INDEX('MO Store'!C:C,MATCH('Overtime 01 - 07 Apr'!$H3,'MO Store'!$A:$A,0)) -> Texas City | H3: 180413 | I3: 04/07/2026 | J3: A00P | K3: AJALA, SEGUN | L3: Retail Store Manager I | M3: 1.19
A4: =INDEX('MO Store'!D:D,MATCH('Overtime 01 - 07 Apr'!$H4,'MO Store'!$A:$A,0)) -> Anthony Galichet | B4: =INDEX('MO Store'!F:F,MATCH('Overtime 01 - 07 Apr'!$H4,'MO Store'!$A:$A,0)) -> No SD | C4: =IFERROR(INDEX('MO Store'!G:G,MATCH('Overtime 01 - 07 Apr'!$H4,'MO Store'!$A:$A,0)),"") -> Susu Leong | D4: =INDEX('MO Store'!E:E,MATCH('Overtime 01 - 07 Apr'!$H4,'MO Store'!$A:$A,0)) -> Brittanie Braggs | E4: =IFERROR(INDEX('MO Store'!H:H,MATCH('Overtime 01 - 07 Apr'!$H4,'MO Store'!$A:$A,0)),"") -> No SEL | F4: =INDEX('MO Store'!B:B,MATCH('Overtime 01 - 07 Apr'!$H4,'MO Store'!$A:$A,0)) -> Arizona | G4: =INDEX('MO Store'!C:C,MATCH('Overtime 01 - 07 Apr'!$H4,'MO Store'!$A:$A,0)) -> Tucson Speedway | H4: 155061 | I4: 04/07/2026 | J4: AWK6 | K4: ALVAREZ, CLAUDIA E | L4: Bilingual Retail Store Manager I | M4: 4.49
A5: =INDEX('MO Store'!D:D,MATCH('Overtime 01 - 07 Apr'!$H5,'MO Store'!$A:$A,0)) -> Anthony Galichet | B5: =INDEX('MO Store'!F:F,MATCH('Overtime 01 - 07 Apr'!$H5,'MO Store'!$A:$A,0)) -> Romio Hamdar | C5: =IFERROR(INDEX('MO Store'!G:G,MATCH('Overtime 01 - 07 Apr'!$H5,'MO Store'!$A:$A,0)),"") -> Austin TM | D5: =INDEX('MO Store'!E:E,MATCH('Overtime 01 - 07 Apr'!$H5,'MO Store'!$A:$A,0)) -> Brittanie Braggs | E5: =IFERROR(INDEX('MO Store'!H:H,MATCH('Overtime 01 - 07 Apr'!$H5,'MO Store'!$A:$A,0)),"") -> No SEL | F5: =INDEX('MO Store'!B:B,MATCH('Overtime 01 - 07 Apr'!$H5,'MO Store'!$A:$A,0)) -> Austin | G5: =INDEX('MO Store'!C:C,MATCH('Overtime 01 - 07 Apr'!$H5,'MO Store'!$A:$A,0)) -> OLTORF | H5: 176020 | I5: 04/07/2026 | J5: AWT2 | K5: ARROYO, SAHIRA GISSELLE | L5: Bilingual Connectivity Expert | M5: 6.26
A6: =INDEX('MO Store'!D:D,MATCH('Overtime 01 - 07 Apr'!$H6,'MO Store'!$A:$A,0)) -> Anthony Galichet | B6: =INDEX('MO Store'!F:F,MATCH('Overtime 01 - 07 Apr'!$H6,'MO Store'!$A:$A,0)) -> Romio Hamdar | C6: =IFERROR(INDEX('MO Store'!G:G,MATCH('Overtime 01 - 07 Apr'!$H6,'MO Store'!$A:$A,0)),"") -> Austin TM | D6: =INDEX('MO Store'!E:E,MATCH('Overtime 01 - 07 Apr'!$H6,'MO Store'!$A:$A,0)) -> Brittanie Braggs | E6: =IFERROR(INDEX('MO Store'!H:H,MATCH('Overtime 01 - 07 Apr'!$H6,'MO Store'!$A:$A,0)),"") -> No SEL | F6: =INDEX('MO Store'!B:B,MATCH('Overtime 01 - 07 Apr'!$H6,'MO Store'!$A:$A,0)) -> Austin | G6: =INDEX('MO Store'!C:C,MATCH('Overtime 01 - 07 Apr'!$H6,'MO Store'!$A:$A,0)) -> Rutland | H6: 152336 | I6: 04/07/2026 | J6: AXGA | K6: CARRILLO, MARÃA VALENTINA | L6: Bilingual Connectivity Expert | M6: 0.12
A7: =INDEX('MO Store'!D:D,MATCH('Overtime 01 - 07 Apr'!$H7,'MO Store'!$A:$A,0)) -> Anthony Galichet | B7: =INDEX('MO Store'!F:F,MATCH('Overtime 01 - 07 Apr'!$H7,'MO Store'!$A:$A,0)) -> No SD | C7: =IFERROR(INDEX('MO Store'!G:G,MATCH('Overtime 01 - 07 Apr'!$H7,'MO Store'!$A:$A,0)),"") -> Jayme Roraff | D7: =INDEX('MO Store'!E:E,MATCH('Overtime 01 - 07 Apr'!$H7,'MO Store'!$A:$A,0)) -> Brittanie Braggs | E7: =IFERROR(INDEX('MO Store'!H:H,MATCH('Overtime 01 - 07 Apr'!$H7,'MO Store'!$A:$A,0)),"") -> No SEL | F7: =INDEX('MO Store'!B:B,MATCH('Overtime 01 - 07 Apr'!$H7,'MO Store'!$A:$A,0)) -> Wisconsin West | G7: =INDEX('MO Store'!C:C,MATCH('Overtime 01 - 07 Apr'!$H7,'MO Store'!$A:$A,0)) -> Richland Center | H7: 240355 | I7: 04/06/2026 | J7: A3AQ | K7: CLARK, CHASE JAMES | L7: Connectivity Expert | M7: 1.75
A8: =INDEX('MO Store'!D:D,MATCH('Overtime 01 - 07 Apr'!$H8,'MO Store'!$A:$A,0)) -> Anthony Galichet | B8: =INDEX('MO Store'!F:F,MATCH('Overtime 01 - 07 Apr'!$H8,'MO Store'!$A:$A,0)) -> No SD | C8: =IFERROR(INDEX('MO Store'!G:G,MATCH('Overtime 01 - 07 Apr'!$H8,'MO Store'!$A:$A,0)),"") -> Jayme Roraff | D8: =INDEX('MO Store'!E:E,MATCH('Overtime 01 - 07 Apr'!$H8,'MO Store'!$A:$A,0)) -> Brittanie Braggs | E8: =IFERROR(INDEX('MO Store'!H:H,MATCH('Overtime 01 - 07 Apr'!$H8,'MO Store'!$A:$A,0)),"") -> No SEL | F8: =INDEX('MO Store'!B:B,MATCH('Overtime 01 - 07 Apr'!$H8,'MO Store'!$A:$A,0)) -> Wisconsin West | G8: =INDEX('MO Store'!C:C,MATCH('Overtime 01 - 07 Apr'!$H8,'MO Store'!$A:$A,0)) -> Tomah Buan Street | H8: 180228 | I8: 04/06/2026 | J8: AXLK | K8: DEWEES, OZZY DOKKEN | L8: Connectivity Expert | M8: 1.04
A9: =INDEX('MO Store'!D:D,MATCH('Overtime 01 - 07 Apr'!$H9,'MO Store'!$A:$A,0)) -> Anthony Galichet | B9: =INDEX('MO Store'!F:F,MATCH('Overtime 01 - 07 Apr'!$H9,'MO Store'!$A:$A,0)) -> No SD | C9: =IFERROR(INDEX('MO Store'!G:G,MATCH('Overtime 01 - 07 Apr'!$H9,'MO Store'!$A:$A,0)),"") -> Jayme Roraff | D9: =INDEX('MO Store'!E:E,MATCH('Overtime 01 - 07 Apr'!$H9,'MO Store'!$A:$A,0)) -> Brittanie Braggs | E9: =IFERROR(INDEX('MO Store'!H:H,MATCH('Overtime 01 - 07 Apr'!$H9,'MO Store'!$A:$A,0)),"") -> No SEL | F9: =INDEX('MO Store'!B:B,MATCH('Overtime 01 - 07 Apr'!$H9,'MO Store'!$A:$A,0)) -> Wisconsin West | G9: =INDEX('MO Store'!C:C,MATCH('Overtime 01 - 07 Apr'!$H9,'MO Store'!$A:$A,0)) -> Tomah Buan Street | H9: 180228 | I9: 04/07/2026 | J9: AXLK | K9: DEWEES, OZZY DOKKEN | L9: Connectivity Expert | M9: 8.12
A10: =INDEX('MO Store'!D:D,MATCH('Overtime 01 - 07 Apr'!$H10,'MO Store'!$A:$A,0)) -> Anthony Galichet | B10: =INDEX('MO Store'!F:F,MATCH('Overtime 01 - 07 Apr'!$H10,'MO Store'!$A:$A,0)) -> No SD | C10: =IFERROR(INDEX('MO Store'!G:G,MATCH('Overtime 01 - 07 Apr'!$H10,'MO Store'!$A:$A,0)),"") -> Susu Leong | D10: =INDEX('MO Store'!E:E,MATCH('Overtime 01 - 07 Apr'!$H10,'MO Store'!$A:$A,0)) -> Brittanie Braggs | E10: =IFERROR(INDEX('MO Store'!H:H,MATCH('Overtime 01 - 07 Apr'!$H10,'MO Store'!$A:$A,0)),"") -> No SEL | F10: =INDEX('MO Store'!B:B,MATCH('Overtime 01 - 07 Apr'!$H10,'MO Store'!$A:$A,0)) -> Arizona | G10: =INDEX('MO Store'!C:C,MATCH('Overtime 01 - 07 Apr'!$H10,'MO Store'!$A:$A,0)) -> The Groves | H10: 211579 | I10: 04/07/2026 | J10: AXC3 | K10: DIAZ, EDDIE | L10: Bilingual Connectivity Expert | M10: 2.53
A11: =INDEX('MO Store'!D:D,MATCH('Overtime 01 - 07 Apr'!$H11,'MO Store'!$A:$A,0)) -> Anthony Galichet | B11: =INDEX('MO Store'!F:F,MATCH('Overtime 01 - 07 Apr'!$H11,'MO Store'!$A:$A,0)) -> Romio Hamdar | C11: =IFERROR(INDEX('MO Store'!G:G,MATCH('Overtime 01 - 07 Apr'!$H11,'MO Store'!$A:$A,0)),"") -> Suhail Ishaq | D11: =INDEX('MO Store'!E:E,MATCH('Overtime 01 - 07 Apr'!$H11,'MO Store'!$A:$A,0)) -> Brittanie Braggs | E11: =IFERROR(INDEX('MO Store'!H:H,MATCH('Overtime 01 - 07 Apr'!$H11,'MO Store'!$A:$A,0)),"") -> No SEL | F11: =INDEX('MO Store'!B:B,MATCH('Overtime 01 - 07 Apr'!$H11,'MO Store'!$A:$A,0)) -> Houston North East | G11: =INDEX('MO Store'!C:C,MATCH('Overtime 01 - 07 Apr'!$H11,'MO Store'!$A:$A,0)) -> Ponderosa Forest | H11: 209868 | I11: 04/06/2026 | J11: A3C8 | K11: FAJARDO, ANDY JOSUE | L11: Bilingual Retail Store Manager I | M11: 4.05
A12: =INDEX('MO Store'!D:D,MATCH('Overtime 01 - 07 Apr'!$H12,'MO Store'!$A:$A,0)) -> Anthony Galichet | B12: =INDEX('MO Store'!F:F,MATCH('Overtime 01 - 07 Apr'!$H12,'MO Store'!$A:$A,0)) -> No SD | C12: =IFERROR(INDEX('MO Store'!G:G,MATCH('Overtime 01 - 07 Apr'!$H12,'MO Store'!$A:$A,0)),"") -> Jayme Roraff | D12: =INDEX('MO Store'!E:E,MATCH('Overtime 01 - 07 Apr'!$H12,'MO Store'!$A:$A,0)) -> Brittanie Braggs | E12: =IFERROR(INDEX('MO Store'!H:H,MATCH('Overtime 01 - 07 Apr'!$H12,'MO Store'!$A:$A,0)),"") -> No SEL | F12: =INDEX('MO Store'!B:B,MATCH('Overtime 01 - 07 Apr'!$H12,'MO Store'!$A:$A,0)) -> Wisconsin West | G12: =INDEX('MO Store'!C:C,MATCH('Overtime 01 - 07 Apr'!$H12,'MO Store'!$A:$A,0)) -> Onalaska | H12: 180225 | I12: 04/07/2026 | J12: A98Y | K12: FERGUSON, JUSTIN EDWARD | L12: Connectivity Expert | M12: 0.79
A13: =INDEX('MO Store'!D:D,MATCH('Overtime 01 - 07 Apr'!$H13,'MO Store'!$A:$A,0)) -> Anthony Galichet | B13: =INDEX('MO Store'!F:F,MATCH('Overtime 01 - 07 Apr'!$H13,'MO Store'!$A:$A,0)) -> Romio Hamdar | C13: =IFERROR(INDEX('MO Store'!G:G,MATCH('Overtime 01 - 07 Apr'!$H13,'MO Store'!$A:$A,0)),"") -> Carlos Ayala-Level Up | D13: =INDEX('MO Store'!E:E,MATCH('Overtime 01 - 07 Apr'!$H13,'MO Store'!$A:$A,0)) -> Brittanie Braggs | E13: =IFERROR(INDEX('MO Store'!H:H,MATCH('Overtime 01 - 07 Apr'!$H13,'MO Store'!$A:$A,0)),"") -> No SEL | F13: =INDEX('MO Store'!B:B,MATCH('Overtime 01 - 07 Apr'!$H13,'MO Store'!$A:$A,0)) -> Houston South West | G13: =INDEX('MO Store'!C:C,MATCH('Overtime 01 - 07 Apr'!$H13,'MO Store'!$A:$A,0)) -> Westheimer Tanglewilde | H13: 209864 | I13: 04/07/2026 | J13: AVW3 | K13: FUENTES, ANTONY ALEXANDER | L13: Bilingual Connectivity Expert | M13: 1.67
A14: =INDEX('MO Store'!D:D,MATCH('Overtime 01 - 07 Apr'!$H14,'MO Store'!$A:$A,0)) -> Anthony Galichet | B14: =INDEX('MO Store'!F:F,MATCH('Overtime 01 - 07 Apr'!$H14,'MO Store'!$A:$A,0)) -> Romio Hamdar | C14: =IFERROR(INDEX('MO Store'!G:G,MATCH('Overtime 01 - 07 Apr'!$H14,'MO Store'!$A:$A,0)),"") -> Isreal Gomez- Level Up | D14: =INDEX('MO Store'!E:E,MATCH('Overtime 01 - 07 Apr'!$H14,'MO Store'!$A:$A,0)) -> Brittanie Braggs | E14: =IFERROR(INDEX('MO Store'!H:H,MATCH('Overtime 01 - 07 Apr'!$H14,'MO Store'!$A:$A,0)),"") -> No SEL | F14: =INDEX('MO Store'!B:B,MATCH('Overtime 01 - 07 Apr'!$H14,'MO Store'!$A:$A,0)) -> Houston East | G14: =INDEX('MO Store'!C:C,MATCH('Overtime 01 - 07 Apr'!$H14,'MO Store'!$A:$A,0)) -> Deer Park | H14: 209870 | I14: 04/06/2026 | J14: AXL5 | K14: GARCIA, STEVEN JAMES | L14: Retail Store Manager I | M14: 1.23
... A38: =INDEX('MO Store'!D:D,MATCH('Overtime 01 - 07 Apr'!$H38,'MO Store'!$A:$A,0)) -> Anthony Galichet | B38: =INDEX('MO Store'!F:F,MATCH('Overtime 01 - 07 Apr'!$H38,'MO Store'!$A:$A,0)) -> Romio Hamdar | C38: =IFERROR(INDEX('MO Store'!G:G,MATCH('Overtime 01 - 07 Apr'!$H38,'MO Store'!$A:$A,0)),"") -> Colorado Market - No TM | D38: =INDEX('MO Store'!E:E,MATCH('Overtime 01 - 07 Apr'!$H38,'MO Store'!$A:$A,0)) -> Brittanie Braggs | E38: =IFERROR(INDEX('MO Store'!H:H,MATCH('Overtime 01 - 07 Apr'!$H38,'MO Store'!$A:$A,0)),"") -> No SEL | F38: =INDEX('MO Store'!B:B,MATCH('Overtime 01 - 07 Apr'!$H38,'MO Store'!$A:$A,0)) -> Colorado | G38: =INDEX('MO Store'!C:C,MATCH('Overtime 01 - 07 Apr'!$H38,'MO Store'!$A:$A,0)) -> Fountain MESA ROAD | H38: 178719 | I38: 04/07/2026 | J38: AV2Y | K38: WORSHAM, CHARLENE TORRES | L38: Bilingual Connectivity Expert | M38: 0.66

Sheet Overtime 08 - 13 Apr
L1: Total | M1: =SUBTOTAL(9,M3:M1048576) -> 39.4
A2: VP | B2: SD | C2: TM | D2: HRBP | E2: SEL | F2: Market | G2: Store | H2: UID | I2: Date | J2: Paycom ID | K2: Name | L2: Role | M2: Hours
A3: =INDEX('MO Store'!D:D,MATCH('Overtime 08 - 13 Apr'!$H3,'MO Store'!$A:$A,0)) -> Anthony Galichet | B3: =INDEX('MO Store'!F:F,MATCH('Overtime 08 - 13 Apr'!$H3,'MO Store'!$A:$A,0)) -> Romio Hamdar | C3: =IFERROR(INDEX('MO Store'!G:G,MATCH('Overtime 08 - 13 Apr'!$H3,'MO Store'!$A:$A,0)),"") -> Austin TM | D3: =INDEX('MO Store'!E:E,MATCH('Overtime 08 - 13 Apr'!$H3,'MO Store'!$A:$A,0)) -> Brittanie Braggs | E3: =IFERROR(INDEX('MO Store'!H:H,MATCH('Overtime 08 - 13 Apr'!$H3,'MO Store'!$A:$A,0)),"") -> No SEL | F3: =INDEX('MO Store'!B:B,MATCH('Overtime 08 - 13 Apr'!$H3,'MO Store'!$A:$A,0)) -> Austin | G3: =INDEX('MO Store'!C:C,MATCH('Overtime 08 - 13 Apr'!$H3,'MO Store'!$A:$A,0)) -> OLTORF | H3: 176020 | I3: 04/13/2026 | J3: AWT2 | K3: ARROYO, SAHIRA GISSELLE | L3: Bilingual Connectivity Expert | M3: 4.88
A4: =INDEX('MO Store'!D:D,MATCH('Overtime 08 - 13 Apr'!$H4,'MO Store'!$A:$A,0)) -> Anthony Galichet | B4: =INDEX('MO Store'!F:F,MATCH('Overtime 08 - 13 Apr'!$H4,'MO Store'!$A:$A,0)) -> No SD | C4: =IFERROR(INDEX('MO Store'!G:G,MATCH('Overtime 08 - 13 Apr'!$H4,'MO Store'!$A:$A,0)),"") -> Susu Leong | D4: =INDEX('MO Store'!E:E,MATCH('Overtime 08 - 13 Apr'!$H4,'MO Store'!$A:$A,0)) -> Brittanie Braggs | E4: =IFERROR(INDEX('MO Store'!H:H,MATCH('Overtime 08 - 13 Apr'!$H4,'MO Store'!$A:$A,0)),"") -> No SEL | F4: =INDEX('MO Store'!B:B,MATCH('Overtime 08 - 13 Apr'!$H4,'MO Store'!$A:$A,0)) -> Arizona | G4: =INDEX('MO Store'!C:C,MATCH('Overtime 08 - 13 Apr'!$H4,'MO Store'!$A:$A,0)) -> The Groves | H4: 211579 | I4: 04/12/2026 | J4: AXH7 | K4: BARAHONA, ADAN ROGER | L4: Bilingual Connectivity Expert | M4: 0.44
A5: =INDEX('MO Store'!D:D,MATCH('Overtime 08 - 13 Apr'!$H5,'MO Store'!$A:$A,0)) -> Anthony Galichet | B5: =INDEX('MO Store'!F:F,MATCH('Overtime 08 - 13 Apr'!$H5,'MO Store'!$A:$A,0)) -> No SD | C5: =IFERROR(INDEX('MO Store'!G:G,MATCH('Overtime 08 - 13 Apr'!$H5,'MO Store'!$A:$A,0)),"") -> Susu Leong | D5: =INDEX('MO Store'!E:E,MATCH('Overtime 08 - 13 Apr'!$H5,'MO Store'!$A:$A,0)) -> Brittanie Braggs | E5: =IFERROR(INDEX('MO Store'!H:H,MATCH('Overtime 08 - 13 Apr'!$H5,'MO Store'!$A:$A,0)),"") -> No SEL | F5: =INDEX('MO Store'!B:B,MATCH('Overtime 08 - 13 Apr'!$H5,'MO Store'!$A:$A,0)) -> Arizona | G5: =INDEX('MO Store'!C:C,MATCH('Overtime 08 - 13 Apr'!$H5,'MO Store'!$A:$A,0)) -> The Groves | H5: 211579 | I5: 04/13/2026 | J5: AXH7 | K5: BARAHONA, ADAN ROGER | L5: Bilingual Connectivity Expert | M5: 8.3
A6: =INDEX('MO Store'!D:D,MATCH('Overtime 08 - 13 Apr'!$H6,'MO Store'!$A:$A,0)) -> Anthony Galichet | B6: =INDEX('MO Store'!F:F,MATCH('Overtime 08 - 13 Apr'!$H6,'MO Store'!$A:$A,0)) -> Romio Hamdar | C6: =IFERROR(INDEX('MO Store'!G:G,MATCH('Overtime 08 - 13 Apr'!$H6,'MO Store'!$A:$A,0)),"") -> Isreal Gomez- Level Up | D6: =INDEX('MO Store'!E:E,MATCH('Overtime 08 - 13 Apr'!$H6,'MO Store'!$A:$A,0)) -> Brittanie Braggs | E6: =IFERROR(INDEX('MO Store'!H:H,MATCH('Overtime 08 - 13 Apr'!$H6,'MO Store'!$A:$A,0)),"") -> No SEL | F6: =INDEX('MO Store'!B:B,MATCH('Overtime 08 - 13 Apr'!$H6,'MO Store'!$A:$A,0)) -> Houston East | G6: =INDEX('MO Store'!C:C,MATCH('Overtime 08 - 13 Apr'!$H6,'MO Store'!$A:$A,0)) -> Deer Park | H6: 209870 | I6: 04/12/2026 | J6: AXL5 | K6: GARCIA, STEVEN JAMES | L6: Retail Store Manager I | M6: 2.82
A7: =INDEX('MO Store'!D:D,MATCH('Overtime 08 - 13 Apr'!$H7,'MO Store'!$A:$A,0)) -> Anthony Galichet | B7: =INDEX('MO Store'!F:F,MATCH('Overtime 08 - 13 Apr'!$H7,'MO Store'!$A:$A,0)) -> Romio Hamdar | C7: =IFERROR(INDEX('MO Store'!G:G,MATCH('Overtime 08 - 13 Apr'!$H7,'MO Store'!$A:$A,0)),"") -> Isreal Gomez- Level Up | D7: =INDEX('MO Store'!E:E,MATCH('Overtime 08 - 13 Apr'!$H7,'MO Store'!$A:$A,0)) -> Brittanie Braggs | E7: =IFERROR(INDEX('MO Store'!H:H,MATCH('Overtime 08 - 13 Apr'!$H7,'MO Store'!$A:$A,0)),"") -> No SEL | F7: =INDEX('MO Store'!B:B,MATCH('Overtime 08 - 13 Apr'!$H7,'MO Store'!$A:$A,0)) -> Houston East | G7: =INDEX('MO Store'!C:C,MATCH('Overtime 08 - 13 Apr'!$H7,'MO Store'!$A:$A,0)) -> Deer Park | H7: 209870 | I7: 04/13/2026 | J7: AXL5 | K7: GARCIA, STEVEN JAMES | L7: Retail Store Manager I | M7: 9.65
A8: =INDEX('MO Store'!D:D,MATCH('Overtime 08 - 13 Apr'!$H8,'MO Store'!$A:$A,0)) -> Anthony Galichet | B8: =INDEX('MO Store'!F:F,MATCH('Overtime 08 - 13 Apr'!$H8,'MO Store'!$A:$A,0)) -> Romio Hamdar | C8: =IFERROR(INDEX('MO Store'!G:G,MATCH('Overtime 08 - 13 Apr'!$H8,'MO Store'!$A:$A,0)),"") -> Isreal Gomez- Level Up | D8: =INDEX('MO Store'!E:E,MATCH('Overtime 08 - 13 Apr'!$H8,'MO Store'!$A:$A,0)) -> Brittanie Braggs | E8: =IFERROR(INDEX('MO Store'!H:H,MATCH('Overtime 08 - 13 Apr'!$H8,'MO Store'!$A:$A,0)),"") -> No SEL | F8: =INDEX('MO Store'!B:B,MATCH('Overtime 08 - 13 Apr'!$H8,'MO Store'!$A:$A,0)) -> Houston East | G8: =INDEX('MO Store'!C:C,MATCH('Overtime 08 - 13 Apr'!$H8,'MO Store'!$A:$A,0)) -> Angleton Harvin Dr | H8: 180412 | I8: 04/13/2026 | J8: AX12 | K8: JOHNSON, BARON D | L8: Connectivity Expert | M8: 1
A9: =INDEX('MO Store'!D:D,MATCH('Overtime 08 - 13 Apr'!$H9,'MO Store'!$A:$A,0)) -> Anthony Galichet | B9: =INDEX('MO Store'!F:F,MATCH('Overtime 08 - 13 Apr'!$H9,'MO Store'!$A:$A,0)) -> Romio Hamdar | C9: =IFERROR(INDEX('MO Store'!G:G,MATCH('Overtime 08 - 13 Apr'!$H9,'MO Store'!$A:$A,0)),"") -> Carlos Ayala-Level Up | D9: =INDEX('MO Store'!E:E,MATCH('Overtime 08 - 13 Apr'!$H9,'MO Store'!$A:$A,0)) -> Brittanie Braggs | E9: =IFERROR(INDEX('MO Store'!H:H,MATCH('Overtime 08 - 13 Apr'!$H9,'MO Store'!$A:$A,0)),"") -> No SEL | F9: =INDEX('MO Store'!B:B,MATCH('Overtime 08 - 13 Apr'!$H9,'MO Store'!$A:$A,0)) -> Houston South West | G9: =INDEX('MO Store'!C:C,MATCH('Overtime 08 - 13 Apr'!$H9,'MO Store'!$A:$A,0)) -> Kingsbridge | H9: 209862 | I9: 04/13/2026 | J9: AXJG | K9: MATIN, KASON | L9: Connectivity Expert | M9: 0.87
A10: =INDEX('MO Store'!D:D,MATCH('Overtime 08 - 13 Apr'!$H10,'MO Store'!$A:$A,0)) -> Anthony Galichet | B10: =INDEX('MO Store'!F:F,MATCH('Overtime 08 - 13 Apr'!$H10,'MO Store'!$A:$A,0)) -> No SD | C10: =IFERROR(INDEX('MO Store'!G:G,MATCH('Overtime 08 - 13 Apr'!$H10,'MO Store'!$A:$A,0)),"") -> Susu Leong | D10: =INDEX('MO Store'!E:E,MATCH('Overtime 08 - 13 Apr'!$H10,'MO Store'!$A:$A,0)) -> Brittanie Braggs | E10: =IFERROR(INDEX('MO Store'!H:H,MATCH('Overtime 08 - 13 Apr'!$H10,'MO Store'!$A:$A,0)),"") -> No SEL | F10: =INDEX('MO Store'!B:B,MATCH('Overtime 08 - 13 Apr'!$H10,'MO Store'!$A:$A,0)) -> Arizona | G10: =INDEX('MO Store'!C:C,MATCH('Overtime 08 - 13 Apr'!$H10,'MO Store'!$A:$A,0)) -> Old Vail Plaza | H10: 222262 | I10: 04/13/2026 | J10: AXS0 | K10: RUDH, DREW ETHAN | L10: Connectivity Expert | M10: 0.26
A11: =INDEX('MO Store'!D:D,MATCH('Overtime 08 - 13 Apr'!$H11,'MO Store'!$A:$A,0)) -> Anthony Galichet | B11: =INDEX('MO Store'!F:F,MATCH('Overtime 08 - 13 Apr'!$H11,'MO Store'!$A:$A,0)) -> Romio Hamdar | C11: =IFERROR(INDEX('MO Store'!G:G,MATCH('Overtime 08 - 13 Apr'!$H11,'MO Store'!$A:$A,0)),"") -> Suhail Ishaq | D11: =INDEX('MO Store'!E:E,MATCH('Overtime 08 - 13 Apr'!$H11,'MO Store'!$A:$A,0)) -> Brittanie Braggs | E11: =IFERROR(INDEX('MO Store'!H:H,MATCH('Overtime 08 - 13 Apr'!$H11,'MO Store'!$A:$A,0)),"") -> No SEL | F11: =INDEX('MO Store'!B:B,MATCH('Overtime 08 - 13 Apr'!$H11,'MO Store'!$A:$A,0)) -> Houston North East | G11: =INDEX('MO Store'!C:C,MATCH('Overtime 08 - 13 Apr'!$H11,'MO Store'!$A:$A,0)) -> Midtown | H11: 176027 | I11: 04/13/2026 | J11: AXAM | K11: SANCHEZ, JOSE ANTONIO | L11: Bilingual Connectivity Expert | M11: 2.31
A12: =INDEX('MO Store'!D:D,MATCH('Overtime 08 - 13 Apr'!$H12,'MO Store'!$A:$A,0)) -> Anthony Galichet | B12: =INDEX('MO Store'!F:F,MATCH('Overtime 08 - 13 Apr'!$H12,'MO Store'!$A:$A,0)) -> Romio Hamdar | C12: =IFERROR(INDEX('MO Store'!G:G,MATCH('Overtime 08 - 13 Apr'!$H12,'MO Store'!$A:$A,0)),"") -> Isreal Gomez- Level Up | D12: =INDEX('MO Store'!E:E,MATCH('Overtime 08 - 13 Apr'!$H12,'MO Store'!$A:$A,0)) -> Brittanie Braggs | E12: =IFERROR(INDEX('MO Store'!H:H,MATCH('Overtime 08 - 13 Apr'!$H12,'MO Store'!$A:$A,0)),"") -> No SEL | F12: =INDEX('MO Store'!B:B,MATCH('Overtime 08 - 13 Apr'!$H12,'MO Store'!$A:$A,0)) -> Houston East | G12: =INDEX('MO Store'!C:C,MATCH('Overtime 08 - 13 Apr'!$H12,'MO Store'!$A:$A,0)) -> Fairmont Pkwy | H12: 209869 | I12: 04/13/2026 | J12: AVIN | K12: VALENCIA, JOSE ANTONIO | L12: Bilingual Store Lead | M12: 8.7
A13: =INDEX('MO Store'!D:D,MATCH('Overtime 08 - 13 Apr'!$H13,'MO Store'!$A:$A,0)) -> Anthony Galichet | B13: =INDEX('MO Store'!F:F,MATCH('Overtime 08 - 13 Apr'!$H13,'MO Store'!$A:$A,0)) -> Romio Hamdar | C13: =IFERROR(INDEX('MO Store'!G:G,MATCH('Overtime 08 - 13 Apr'!$H13,'MO Store'!$A:$A,0)),"") -> Veronica Ramos | D13: =INDEX('MO Store'!E:E,MATCH('Overtime 08 - 13 Apr'!$H13,'MO Store'!$A:$A,0)) -> Brittanie Braggs | E13: =IFERROR(INDEX('MO Store'!H:H,MATCH('Overtime 08 - 13 Apr'!$H13,'MO Store'!$A:$A,0)),"") -> No SEL | F13: =INDEX('MO Store'!B:B,MATCH('Overtime 08 - 13 Apr'!$H13,'MO Store'!$A:$A,0)) -> San Antonio/Laredo | G13: =INDEX('MO Store'!C:C,MATCH('Overtime 08 - 13 Apr'!$H13,'MO Store'!$A:$A,0)) -> San Pedro | H13: 215746 | I13: 04/13/2026 | J13: AXR9 | K13: WILMOTH, NICHOLAS TAYLOR | L13: Bilingual Store Lead | M13: 0.17

Sheet Lab Tracker 08 - 13 Apr
A1: Labour Tracking As of 08 - 13 Apr 2026 | E1: 45630 | F1: 45630 | G1: Total | I1: =SUBTOTAL(9,I3:I67) -> 10061.6 | J1: =SUBTOTAL(9,J3:J67) -> 7112.92 | K1: =SUBTOTAL(9,K3:K67) -> 39.4 | L1: =SUBTOTAL(9,L3:L67) -> 0 | M1: =SUBTOTAL(9,M3:M714) -> 7152.32 | N1: =SUBTOTAL(9,N3:N67) -> 2909.28 | O1: =SUBTOTAL(9,O3:O1048576) -> 0 | P1: =SUBTOTAL(9,P3:P1048576) -> 0 | Q1: =SUBTOTAL(9,Q3:Q1048576) -> 0
A2: Unique ID | B2: Market | C2: Store | D2: VP | E2: SD | F2: TM | G2: Tiers | H2: Dealer Code | I2: Weekly Budgeted HRS | J2: Regular Hours | K2: Overtime Hours | L2: Other Hours | M2: Total Hours | N2: (+ / -) Budgeted Hours | O2: MIS Approved OT | P2: MIS Unapproved OT | Q2: Total OT
A3: 176028 | B3: =_xlfn.IFNA(VLOOKUP(A3,'MO Store'!A:J,2,0),"NA") -> Houston East | C3: =VLOOKUP(A3,'MO Store'!A:J,3,0) -> Falls Creek Humble | D3: =VLOOKUP(A3,'MO Store'!A:J,4,0) -> Anthony Galichet | E3: =VLOOKUP(A3,'MO Store'!A:J,6,0) -> Romio Hamdar | F3: =VLOOKUP(A3,'MO Store'!A:J,7,0) -> Isreal Gomez- Level Up | G3: =VLOOKUP(A3,'MO Store'!A:J,9,0) -> Battleship | H3: =VLOOKUP(A3,'MO Store'!A:J,10,0) -> P9IFS | I3: 175 | J3: 120.35 | K3: 0 | L3: 0 | M3: =SUM(Budgeted_Hrs[[#This Row],[Regular Hours]:[Other Hours ]]) -> 120.35 | N3: =I3-M3 -> 54.65 | O3: 0 | P3: 0 | Q3: =SUM(Budgeted_Hrs[[#This Row],[MIS Approved OT]:[MIS Unapproved OT]]) -> 0
A4: 215661 | B4: =_xlfn.IFNA(VLOOKUP(A4,'MO Store'!A:J,2,0),"NA") -> Houston East | C4: =VLOOKUP(A4,'MO Store'!A:J,3,0) -> Jasper | D4: =VLOOKUP(A4,'MO Store'!A:J,4,0) -> Anthony Galichet | E4: =VLOOKUP(A4,'MO Store'!A:J,6,0) -> Romio Hamdar | F4: =VLOOKUP(A4,'MO Store'!A:J,7,0) -> Isreal Gomez- Level Up | G4: =VLOOKUP(A4,'MO Store'!A:J,9,0) -> Regular | H4: =VLOOKUP(A4,'MO Store'!A:J,10,0) -> 6C0KB | I4: 157 | J4: 48.13 | K4: 0 | L4: 0 | M4: =SUM(Budgeted_Hrs[[#This Row],[Regular Hours]:[Other Hours ]]) -> 48.13 | N4: =I4-M4 -> 108.87 | O4: 0 | P4: 0 | Q4: =SUM(Budgeted_Hrs[[#This Row],[MIS Approved OT]:[MIS Unapproved OT]]) -> 0
A5: 209868 | B5: =_xlfn.IFNA(VLOOKUP(A5,'MO Store'!A:J,2,0),"NA") -> Houston North East | C5: =VLOOKUP(A5,'MO Store'!A:J,3,0) -> Ponderosa Forest | D5: =VLOOKUP(A5,'MO Store'!A:J,4,0) -> Anthony Galichet | E5: =VLOOKUP(A5,'MO Store'!A:J,6,0) -> Romio Hamdar | F5: =VLOOKUP(A5,'MO Store'!A:J,7,0) -> Suhail Ishaq | G5: =VLOOKUP(A5,'MO Store'!A:J,9,0) -> Regular | H5: =VLOOKUP(A5,'MO Store'!A:J,10,0) -> YLXY5 | I5: 157 | J5: 121.27 | K5: 0 | L5: 0 | M5: =SUM(Budgeted_Hrs[[#This Row],[Regular Hours]:[Other Hours ]]) -> 121.27 | N5: =I5-M5 -> 35.73 | O5: 0 | P5: 0 | Q5: =SUM(Budgeted_Hrs[[#This Row],[MIS Approved OT]:[MIS Unapproved OT]]) -> 0
A6: 209869 | B6: =_xlfn.IFNA(VLOOKUP(A6,'MO Store'!A:J,2,0),"NA") -> Houston East | C6: =VLOOKUP(A6,'MO Store'!A:J,3,0) -> Fairmont Pkwy | D6: =VLOOKUP(A6,'MO Store'!A:J,4,0) -> Anthony Galichet | E6: =VLOOKUP(A6,'MO Store'!A:J,6,0) -> Romio Hamdar | F6: =VLOOKUP(A6,'MO Store'!A:J,7,0) -> Isreal Gomez- Level Up | G6: =VLOOKUP(A6,'MO Store'!A:J,9,0) -> Focus | H6: =VLOOKUP(A6,'MO Store'!A:J,10,0) -> C9ZNE | I6: 115 | J6: 53.8 | K6: 8.7 | L6: 0 | M6: =SUM(Budgeted_Hrs[[#This Row],[Regular Hours]:[Other Hours ]]) -> 62.5 | N6: =I6-M6 -> 52.5 | O6: 0 | P6: 0 | Q6: =SUM(Budgeted_Hrs[[#This Row],[MIS Approved OT]:[MIS Unapproved OT]]) -> 0
A7: 209870 | B7: =_xlfn.IFNA(VLOOKUP(A7,'MO Store'!A:J,2,0),"NA") -> Houston East | C7: =VLOOKUP(A7,'MO Store'!A:J,3,0) -> Deer Park | D7: =VLOOKUP(A7,'MO Store'!A:J,4,0) -> Anthony Galichet | E7: =VLOOKUP(A7,'MO Store'!A:J,6,0) -> Romio Hamdar | F7: =VLOOKUP(A7,'MO Store'!A:J,7,0) -> Isreal Gomez- Level Up | G7: =VLOOKUP(A7,'MO Store'!A:J,9,0) -> Regular | H7: =VLOOKUP(A7,'MO Store'!A:J,10,0) -> B2073 | I7: 105 | J7: 83.63 | K7: 12.47 | L7: 0 | M7: =SUM(Budgeted_Hrs[[#This Row],[Regular Hours]:[Other Hours ]]) -> 96.1 | N7: =I7-M7 -> 8.9 | O7: 0 | P7: 0 | Q7: =SUM(Budgeted_Hrs[[#This Row],[MIS Approved OT]:[MIS Unapproved OT]]) -> 0
A8: 217138 | B8: =_xlfn.IFNA(VLOOKUP(A8,'MO Store'!A:J,2,0),"NA") -> Houston South West | C8: =VLOOKUP(A8,'MO Store'!A:J,3,0) -> Little York Rd | D8: =VLOOKUP(A8,'MO Store'!A:J,4,0) -> Anthony Galichet | E8: =VLOOKUP(A8,'MO Store'!A:J,6,0) -> Romio Hamdar | F8: =VLOOKUP(A8,'MO Store'!A:J,7,0) -> Carlos Ayala-Level Up | G8: =VLOOKUP(A8,'MO Store'!A:J,9,0) -> Regular | H8: =VLOOKUP(A8,'MO Store'!A:J,10,0) -> 7ZLZ7 | I8: 157 | J8: 103.08 | K8: 0 | L8: 0 | M8: =SUM(Budgeted_Hrs[[#This Row],[Regular Hours]:[Other Hours ]]) -> 103.08 | N8: =I8-M8 -> 53.92 | O8: 0 | P8: 0 | Q8: =SUM(Budgeted_Hrs[[#This Row],[MIS Approved OT]:[MIS Unapproved OT]]) -> 0
A9: 174112 | B9: =_xlfn.IFNA(VLOOKUP(A9,'MO Store'!A:J,2,0),"NA") -> Houston South West | C9: =VLOOKUP(A9,'MO Store'!A:J,3,0) -> Rice Ave | D9: =VLOOKUP(A9,'MO Store'!A:J,4,0) -> Anthony Galichet | E9: =VLOOKUP(A9,'MO Store'!A:J,6,0) -> Romio Hamdar | F9: =VLOOKUP(A9,'MO Store'!A:J,7,0) -> Carlos Ayala-Level Up | G9: =VLOOKUP(A9,'MO Store'!A:J,9,0) -> Regular | H9: =VLOOKUP(A9,'MO Store'!A:J,10,0) -> 6V54M | I9: 140 | J9: 111.76 | K9: 0 | L9: 0 | M9: =SUM(Budgeted_Hrs[[#This Row],[Regular Hours]:[Other Hours ]]) -> 111.76 | N9: =I9-M9 -> 28.24 | O9: 0 | P9: 0 | Q9: =SUM(Budgeted_Hrs[[#This Row],[MIS Approved OT]:[MIS Unapproved OT]]) -> 0
A10: 209865 | B10: =_xlfn.IFNA(VLOOKUP(A10,'MO Store'!A:J,2,0),"NA") -> Houston North East | C10: =VLOOKUP(A10,'MO Store'!A:J,3,0) -> Antoine Town Center | D10: =VLOOKUP(A10,'MO Store'!A:J,4,0) -> Anthony Galichet | E10: =VLOOKUP(A10,'MO Store'!A:J,6,0) -> Romio Hamdar | F10: =VLOOKUP(A10,'MO Store'!A:J,7,0) -> Suhail Ishaq | G10: =VLOOKUP(A10,'MO Store'!A:J,9,0) -> Regular | H10: =VLOOKUP(A10,'MO Store'!A:J,10,0) -> GUOUA | I10: 180 | J10: 115.54 | K10: 0 | L10: 0 | M10: =SUM(Budgeted_Hrs[[#This Row],[Regular Hours]:[Other Hours ]]) -> 115.54 | N10: =I10-M10 -> 64.46 | O10: 0 | P10: 0 | Q10: =SUM(Budgeted_Hrs[[#This Row],[MIS Approved OT]:[MIS Unapproved OT]]) -> 0
A11: 174113 | B11: =_xlfn.IFNA(VLOOKUP(A11,'MO Store'!A:J,2,0),"NA") -> Houston North East | C11: =VLOOKUP(A11,'MO Store'!A:J,3,0) -> Missouri City | D11: =VLOOKUP(A11,'MO Store'!A:J,4,0) -> Anthony Galichet | E11: =VLOOKUP(A11,'MO Store'!A:J,6,0) -> Romio Hamdar | F11: =VLOOKUP(A11,'MO Store'!A:J,7,0) -> Suhail Ishaq | G11: =VLOOKUP(A11,'MO Store'!A:J,9,0) -> Regular | H11: =VLOOKUP(A11,'MO Store'!A:J,10,0) -> 2SFXX | I11: 140 | J11: 75.52 | K11: 0 | L11: 0 | M11: =SUM(Budgeted_Hrs[[#This Row],[Regular Hours]:[Other Hours ]]) -> 75.52 | N11: =I11-M11 -> 64.48 | O11: 0 | P11: 0 | Q11: =SUM(Budgeted_Hrs[[#This Row],[MIS Approved OT]:[MIS Unapproved OT]]) -> 0
A12: 176027 | B12: =_xlfn.IFNA(VLOOKUP(A12,'MO Store'!A:J,2,0),"NA") -> Houston North East | C12: =VLOOKUP(A12,'MO Store'!A:J,3,0) -> Midtown | D12: =VLOOKUP(A12,'MO Store'!A:J,4,0) -> Anthony Galichet | E12: =VLOOKUP(A12,'MO Store'!A:J,6,0) -> Romio Hamdar | F12: =VLOOKUP(A12,'MO Store'!A:J,7,0) -> Suhail Ishaq | G12: =VLOOKUP(A12,'MO Store'!A:J,9,0) -> Battleship | H12: =VLOOKUP(A12,'MO Store'!A:J,10,0) -> CN32O | I12: 157 | J12: 62.6 | K12: 2.31 | L12: 0 | M12: =SUM(Budgeted_Hrs[[#This Row],[Regular Hours]:[Other Hours ]]) -> 64.91 | N12: =I12-M12 -> 92.09 | O12: 0 | P12: 0 | Q12: =SUM(Budgeted_Hrs[[#This Row],[MIS Approved OT]:[MIS Unapproved OT]]) -> 0
A13: 174110 | B13: =_xlfn.IFNA(VLOOKUP(A13,'MO Store'!A:J,2,0),"NA") -> Houston North East | C13: =VLOOKUP(A13,'MO Store'!A:J,3,0) -> Richmond (River Park) | D13: =VLOOKUP(A13,'MO Store'!A:J,4,0) -> Anthony Galichet | E13: =VLOOKUP(A13,'MO Store'!A:J,6,0) -> Romio Hamdar | F13: =VLOOKUP(A13,'MO Store'!A:J,7,0) -> Suhail Ishaq | G13: =VLOOKUP(A13,'MO Store'!A:J,9,0) -> Regular | H13: =VLOOKUP(A13,'MO Store'!A:J,10,0) -> CW6TF | I13: 110 | J13: 120.05 | K13: 0 | L13: 0 | M13: =SUM(Budgeted_Hrs[[#This Row],[Regular Hours]:[Other Hours ]]) -> 120.05 | N13: =I13-M13 -> -10.05 | O13: 0 | P13: 0 | Q13: =SUM(Budgeted_Hrs[[#This Row],[MIS Approved OT]:[MIS Unapproved OT]]) -> 0
A14: 219200 | B14: =_xlfn.IFNA(VLOOKUP(A14,'MO Store'!A:J,2,0),"NA") -> Houston North East | C14: =VLOOKUP(A14,'MO Store'!A:J,3,0) -> Rosenberg | D14: =VLOOKUP(A14,'MO Store'!A:J,4,0) -> Anthony Galichet | E14: =VLOOKUP(A14,'MO Store'!A:J,6,0) -> Romio Hamdar | F14: =VLOOKUP(A14,'MO Store'!A:J,7,0) -> Suhail Ishaq | G14: =VLOOKUP(A14,'MO Store'!A:J,9,0) -> Focus | H14: =VLOOKUP(A14,'MO Store'!A:J,10,0) -> UPT8M | I14: 140 | J14: 76.86 | K14: 0 | L14: 0 | M14: =SUM(Budgeted_Hrs[[#This Row],[Regular Hours]:[Other Hours ]]) -> 76.86 | N14: =I14-M14 -> 63.14 | O14: 0 | P14: 0 | Q14: =SUM(Budgeted_Hrs[[#This Row],[MIS Approved OT]:[MIS Unapproved OT]]) -> 0
... A67: 155061 | B67: =_xlfn.IFNA(VLOOKUP(A67,'MO Store'!A:J,2,0),"NA") -> Arizona | C67: =VLOOKUP(A67,'MO Store'!A:J,3,0) -> Tucson Speedway | D67: =VLOOKUP(A67,'MO Store'!A:J,4,0) -> Anthony Galichet | E67: =VLOOKUP(A67,'MO Store'!A:J,6,0) -> No SD | F67: =VLOOKUP(A67,'MO Store'!A:J,7,0) -> Susu Leong | G67: =VLOOKUP(A67,'MO Store'!A:J,9,0) -> Regular | H67: =VLOOKUP(A67,'MO Store'!A:J,10,0) -> AEPR6 | I67: 105 | J67: 96.91 | K67: 0 | L67: 0 | M67: =SUM(Budgeted_Hrs[[#This Row],[Regular Hours]:[Other Hours ]]) -> 96.91 | N67: =I67-M67 -> 8.09 | O67: 0 | P67: 0 | Q67: =SUM(Budgeted_Hrs[[#This Row],[MIS Approved OT]:[MIS Unapproved OT]]) -> 0

Sheet Approaching OT
A1: Approaching OT of Employees for the period 08 - 13 Apr 2025 | M1: =SUBTOTAL(9,M4:M1630) -> 7152.32 | N1: =SUBTOTAL(9,N164:N1048576) -> 0 | O1: =SUBTOTAL(9,O4:O1048576) -> 0 | P1: =SUBTOTAL(9,P4:P1048576) -> 0
A3: Market | B3: Store | C3: VP | D3: SD | E3: TM | F3: HRBP | G3: Tier | H3: ID | I3: Employee Name | J3: Role | K3: UID | L3: Approaching OT | M3: Total Hours | N3: MIS Approved OT | O3: MIS Unapproved OT | P3: Total OT
A4: =INDEX('MO Store'!B:B,MATCH($K4,'MO Store'!$A:$A,0)) -> Houston North East | B4: =INDEX('MO Store'!C:C,MATCH($K4,'MO Store'!$A:$A,0)) -> Texas City | C4: =INDEX('MO Store'!D:D,MATCH($K4,'MO Store'!$A:$A,0)) -> Anthony Galichet | D4: =INDEX('MO Store'!F:F,MATCH($K4,'MO Store'!$A:$A,0)) -> Romio Hamdar | E4: =INDEX('MO Store'!G:G,MATCH($K4,'MO Store'!$A:$A,0)) -> Suhail Ishaq | F4: =INDEX('MO Store'!E:E,MATCH($K4,'MO Store'!$A:$A,0)) -> Brittanie Braggs | G4: =INDEX('MO Store'!I:I,MATCH($K4,'MO Store'!$A:$A,0)) -> Regular | H4: A00P | I4: SEGUN AJALA | J4: HRSM | K4: 180413 | L4: =IF(M4>35,"Yes","No") -> Yes | M4: 38.21 | N4: 0 | O4: 0 | P4: =SUM(N4:O4) -> 0
A5: =INDEX('MO Store'!B:B,MATCH($K5,'MO Store'!$A:$A,0)) -> Houston South West | B5: =INDEX('MO Store'!C:C,MATCH($K5,'MO Store'!$A:$A,0)) -> Presidio | C5: =INDEX('MO Store'!D:D,MATCH($K5,'MO Store'!$A:$A,0)) -> Anthony Galichet | D5: =INDEX('MO Store'!F:F,MATCH($K5,'MO Store'!$A:$A,0)) -> Romio Hamdar | E5: =INDEX('MO Store'!G:G,MATCH($K5,'MO Store'!$A:$A,0)) -> Carlos Ayala-Level Up | F5: =INDEX('MO Store'!E:E,MATCH($K5,'MO Store'!$A:$A,0)) -> Brittanie Braggs | G5: =INDEX('MO Store'!I:I,MATCH($K5,'MO Store'!$A:$A,0)) -> Regular | H5: AWQU | I5: GIANNI ALANIZ | J5: BCE | K5: 211049 | L5: =IF(M5>35,"Yes","No") -> Yes | M5: 38.65 | N5: 0 | O5: 0 | P5: =SUM(N5:O5) -> 0
A6: =INDEX('MO Store'!B:B,MATCH($K6,'MO Store'!$A:$A,0)) -> Austin | B6: =INDEX('MO Store'!C:C,MATCH($K6,'MO Store'!$A:$A,0)) -> OLTORF | C6: =INDEX('MO Store'!D:D,MATCH($K6,'MO Store'!$A:$A,0)) -> Anthony Galichet | D6: =INDEX('MO Store'!F:F,MATCH($K6,'MO Store'!$A:$A,0)) -> Romio Hamdar | E6: =INDEX('MO Store'!G:G,MATCH($K6,'MO Store'!$A:$A,0)) -> Austin TM | F6: =INDEX('MO Store'!E:E,MATCH($K6,'MO Store'!$A:$A,0)) -> Brittanie Braggs | G6: =INDEX('MO Store'!I:I,MATCH($K6,'MO Store'!$A:$A,0)) -> Regular | H6: AWT2 | I6: SAHIRA ARROYO | J6: BCE | K6: 176020 | L6: =IF(M6>35,"Yes","No") -> Yes | M6: 44.88 | N6: 0 | O6: 0 | P6: =SUM(N6:O6) -> 0
A7: =INDEX('MO Store'!B:B,MATCH($K7,'MO Store'!$A:$A,0)) -> Arizona | B7: =INDEX('MO Store'!C:C,MATCH($K7,'MO Store'!$A:$A,0)) -> The Groves | C7: =INDEX('MO Store'!D:D,MATCH($K7,'MO Store'!$A:$A,0)) -> Anthony Galichet | D7: =INDEX('MO Store'!F:F,MATCH($K7,'MO Store'!$A:$A,0)) -> No SD | E7: =INDEX('MO Store'!G:G,MATCH($K7,'MO Store'!$A:$A,0)) -> Susu Leong | F7: =INDEX('MO Store'!E:E,MATCH($K7,'MO Store'!$A:$A,0)) -> Brittanie Braggs | G7: =INDEX('MO Store'!I:I,MATCH($K7,'MO Store'!$A:$A,0)) -> Regular | H7: AXH7 | I7: ADAN BARAHONA | J7: BCE | K7: 211579 | L7: =IF(M7>35,"Yes","No") -> Yes | M7: 48.74 | N7: 0 | O7: 0 | P7: =SUM(N7:O7) -> 0
A8: =INDEX('MO Store'!B:B,MATCH($K8,'MO Store'!$A:$A,0)) -> Houston South West | B8: =INDEX('MO Store'!C:C,MATCH($K8,'MO Store'!$A:$A,0)) -> Kingsbridge | C8: =INDEX('MO Store'!D:D,MATCH($K8,'MO Store'!$A:$A,0)) -> Anthony Galichet | D8: =INDEX('MO Store'!F:F,MATCH($K8,'MO Store'!$A:$A,0)) -> Romio Hamdar | E8: =INDEX('MO Store'!G:G,MATCH($K8,'MO Store'!$A:$A,0)) -> Carlos Ayala-Level Up | F8: =INDEX('MO Store'!E:E,MATCH($K8,'MO Store'!$A:$A,0)) -> Brittanie Braggs | G8: =INDEX('MO Store'!I:I,MATCH($K8,'MO Store'!$A:$A,0)) -> Regular | H8: A047 | I8: JENNIFER BERMUDEZ GILCES | J8: CE | K8: 209862 | L8: =IF(M8>35,"Yes","No") -> Yes | M8: 35.61 | N8: 0 | O8: 0 | P8: =SUM(N8:O8) -> 0
A9: =INDEX('MO Store'!B:B,MATCH($K9,'MO Store'!$A:$A,0)) -> Colorado | B9: =INDEX('MO Store'!C:C,MATCH($K9,'MO Store'!$A:$A,0)) -> Fountain MESA ROAD | C9: =INDEX('MO Store'!D:D,MATCH($K9,'MO Store'!$A:$A,0)) -> Anthony Galichet | D9: =INDEX('MO Store'!F:F,MATCH($K9,'MO Store'!$A:$A,0)) -> Romio Hamdar | E9: =INDEX('MO Store'!G:G,MATCH($K9,'MO Store'!$A:$A,0)) -> Colorado Market - No TM | F9: =INDEX('MO Store'!E:E,MATCH($K9,'MO Store'!$A:$A,0)) -> Brittanie Braggs | G9: =INDEX('MO Store'!I:I,MATCH($K9,'MO Store'!$A:$A,0)) -> Battleship | H9: A071 | I9: CAMERON CARR | J9: CE | K9: 178719 | L9: =IF(M9>35,"Yes","No") -> Yes | M9: 37.73 | N9: 0 | O9: 0 | P9: =SUM(N9:O9) -> 0
A10: =INDEX('MO Store'!B:B,MATCH($K10,'MO Store'!$A:$A,0)) -> Austin | B10: =INDEX('MO Store'!C:C,MATCH($K10,'MO Store'!$A:$A,0)) -> Rutland | C10: =INDEX('MO Store'!D:D,MATCH($K10,'MO Store'!$A:$A,0)) -> Anthony Galichet | D10: =INDEX('MO Store'!F:F,MATCH($K10,'MO Store'!$A:$A,0)) -> Romio Hamdar | E10: =INDEX('MO Store'!G:G,MATCH($K10,'MO Store'!$A:$A,0)) -> Austin TM | F10: =INDEX('MO Store'!E:E,MATCH($K10,'MO Store'!$A:$A,0)) -> Brittanie Braggs | G10: =INDEX('MO Store'!I:I,MATCH($K10,'MO Store'!$A:$A,0)) -> Regular | H10: AXGA | I10: MARÃA CARRILLO | J10: BCE | K10: 152336 | L10: =IF(M10>35,"Yes","No") -> Yes | M10: 39.62 | N10: 0 | O10: 0 | P10: =SUM(N10:O10) -> 0
A11: =INDEX('MO Store'!B:B,MATCH($K11,'MO Store'!$A:$A,0)) -> San Antonio/Laredo | B11: =INDEX('MO Store'!C:C,MATCH($K11,'MO Store'!$A:$A,0)) -> EAGLE PASS | C11: =INDEX('MO Store'!D:D,MATCH($K11,'MO Store'!$A:$A,0)) -> Anthony Galichet | D11: =INDEX('MO Store'!F:F,MATCH($K11,'MO Store'!$A:$A,0)) -> Romio Hamdar | E11: =INDEX('MO Store'!G:G,MATCH($K11,'MO Store'!$A:$A,0)) -> Veronica Ramos | F11: =INDEX('MO Store'!E:E,MATCH($K11,'MO Store'!$A:$A,0)) -> Brittanie Braggs | G11: =INDEX('MO Store'!I:I,MATCH($K11,'MO Store'!$A:$A,0)) -> Flagship | H11: ARCY | I11: ESMERALDA GALVAN | J11: BCE | K11: 207753 | L11: =IF(M11>35,"Yes","No") -> Yes | M11: 36.72 | N11: 0 | O11: 0 | P11: =SUM(N11:O11) -> 0
A12: =INDEX('MO Store'!B:B,MATCH($K12,'MO Store'!$A:$A,0)) -> Houston East | B12: =INDEX('MO Store'!C:C,MATCH($K12,'MO Store'!$A:$A,0)) -> Deer Park | C12: =INDEX('MO Store'!D:D,MATCH($K12,'MO Store'!$A:$A,0)) -> Anthony Galichet | D12: =INDEX('MO Store'!F:F,MATCH($K12,'MO Store'!$A:$A,0)) -> Romio Hamdar | E12: =INDEX('MO Store'!G:G,MATCH($K12,'MO Store'!$A:$A,0)) -> Isreal Gomez- Level Up | F12: =INDEX('MO Store'!E:E,MATCH($K12,'MO Store'!$A:$A,0)) -> Brittanie Braggs | G12: =INDEX('MO Store'!I:I,MATCH($K12,'MO Store'!$A:$A,0)) -> Regular | H12: AXL5 | I12: STEVEN GARCIA | J12: HRSM | K12: 209870 | L12: =IF(M12>35,"Yes","No") -> Yes | M12: 52.47 | N12: 0 | O12: 0 | P12: =SUM(N12:O12) -> 0
A13: =INDEX('MO Store'!B:B,MATCH($K13,'MO Store'!$A:$A,0)) -> North Carolina | B13: =INDEX('MO Store'!C:C,MATCH($K13,'MO Store'!$A:$A,0)) -> Mocksville | C13: =INDEX('MO Store'!D:D,MATCH($K13,'MO Store'!$A:$A,0)) -> Anthony Galichet | D13: =INDEX('MO Store'!F:F,MATCH($K13,'MO Store'!$A:$A,0)) -> No SD | E13: =INDEX('MO Store'!G:G,MATCH($K13,'MO Store'!$A:$A,0)) -> North Carolina Market - No TM | F13: =INDEX('MO Store'!E:E,MATCH($K13,'MO Store'!$A:$A,0)) -> Brittanie Braggs | G13: =INDEX('MO Store'!I:I,MATCH($K13,'MO Store'!$A:$A,0)) -> Focus | H13: AXPM | I13: DENISE GLASPIE | J13: CE | K13: 221882 | L13: =IF(M13>35,"Yes","No") -> Yes | M13: 35.21 | N13: 0 | O13: 0 | P13: =SUM(N13:O13) -> 0
A14: =INDEX('MO Store'!B:B,MATCH($K14,'MO Store'!$A:$A,0)) -> North Carolina | B14: =INDEX('MO Store'!C:C,MATCH($K14,'MO Store'!$A:$A,0)) -> Durham | C14: =INDEX('MO Store'!D:D,MATCH($K14,'MO Store'!$A:$A,0)) -> Anthony Galichet | D14: =INDEX('MO Store'!F:F,MATCH($K14,'MO Store'!$A:$A,0)) -> No SD | E14: =INDEX('MO Store'!G:G,MATCH($K14,'MO Store'!$A:$A,0)) -> North Carolina Market - No TM | F14: =INDEX('MO Store'!E:E,MATCH($K14,'MO Store'!$A:$A,0)) -> Brittanie Braggs | G14: =INDEX('MO Store'!I:I,MATCH($K14,'MO Store'!$A:$A,0)) -> Regular | H14: ATXI | I14: EDSON GUERRERO VELASQUEZ | J14: HBRSM | K14: 216129 | L14: =IF(M14>35,"Yes","No") -> Yes | M14: 38.83 | N14: 0 | O14: 0 | P14: =SUM(N14:O14) -> 0
A15: =INDEX('MO Store'!B:B,MATCH($K15,'MO Store'!$A:$A,0)) -> San Antonio/Laredo | B15: =INDEX('MO Store'!C:C,MATCH($K15,'MO Store'!$A:$A,0)) -> Wurzbach Road | C15: =INDEX('MO Store'!D:D,MATCH($K15,'MO Store'!$A:$A,0)) -> Anthony Galichet | D15: =INDEX('MO Store'!F:F,MATCH($K15,'MO Store'!$A:$A,0)) -> Romio Hamdar | E15: =INDEX('MO Store'!G:G,MATCH($K15,'MO Store'!$A:$A,0)) -> Veronica Ramos | F15: =INDEX('MO Store'!E:E,MATCH($K15,'MO Store'!$A:$A,0)) -> Brittanie Braggs | G15: =INDEX('MO Store'!I:I,MATCH($K15,'MO Store'!$A:$A,0)) -> Battleship | H15: AV3X | I15: HAILEY GUSTAMANTE | J15: BCE | K15: 215745 | L15: =IF(M15>35,"Yes","No") -> Yes | M15: 38.72 | N15: 0 | O15: 0 | P15: =SUM(N15:O15) -> 0
... A24: =INDEX('MO Store'!B:B,MATCH($K24,'MO Store'!$A:$A,0)) -> San Antonio/Laredo | B24: =INDEX('MO Store'!C:C,MATCH($K24,'MO Store'!$A:$A,0)) -> LAREDO PLANTATION CENTRE | C24: =INDEX('MO Store'!D:D,MATCH($K24,'MO Store'!$A:$A,0)) -> Anthony Galichet | D24: =INDEX('MO Store'!F:F,MATCH($K24,'MO Store'!$A:$A,0)) -> Romio Hamdar | E24: =INDEX('MO Store'!G:G,MATCH($K24,'MO Store'!$A:$A,0)) -> Veronica Ramos | F24: =INDEX('MO Store'!E:E,MATCH($K24,'MO Store'!$A:$A,0)) -> Brittanie Braggs | G24: =INDEX('MO Store'!I:I,MATCH($K24,'MO Store'!$A:$A,0)) -> Flagship | H24: AVTW | I24: KAYLA PEREZ | J24: BCE | K24: 207752 | L24: =IF(M24>35,"Yes","No") -> Yes | M24: 37.59 | N24: 0 | O24: 0 | P24: =SUM(N24:O24) -> 0
A25: =INDEX('MO Store'!B:B,MATCH($K25,'MO Store'!$A:$A,0)) -> San Antonio/Laredo | B25: =INDEX('MO Store'!C:C,MATCH($K25,'MO Store'!$A:$A,0)) -> Laredo Crossing | C25: =INDEX('MO Store'!D:D,MATCH($K25,'MO Store'!$A:$A,0)) -> Anthony Galichet | D25: =INDEX('MO Store'!F:F,MATCH($K25,'MO Store'!$A:$A,0)) -> Romio Hamdar | E25: =INDEX('MO Store'!G:G,MATCH($K25,'MO Store'!$A:$A,0)) -> Veronica Ramos | F25: =INDEX('MO Store'!E:E,MATCH($K25,'MO Store'!$A:$A,0)) -> Brittanie Braggs | G25: Closed | H25: AXF1 | I25: MARTIN ROMERO | J25: BCE | K25: 174067 | L25: =IF(M25>35,"Yes","No") -> Yes | M25: 37.91 | N25: 0 | O25: 0 | P25: =SUM(N25:O25) -> 0
A26: =INDEX('MO Store'!B:B,MATCH($K26,'MO Store'!$A:$A,0)) -> Arizona | B26: =INDEX('MO Store'!C:C,MATCH($K26,'MO Store'!$A:$A,0)) -> Old Vail Plaza | C26: =INDEX('MO Store'!D:D,MATCH($K26,'MO Store'!$A:$A,0)) -> Anthony Galichet | D26: =INDEX('MO Store'!F:F,MATCH($K26,'MO Store'!$A:$A,0)) -> No SD | E26: =INDEX('MO Store'!G:G,MATCH($K26,'MO Store'!$A:$A,0)) -> Susu Leong | F26: =INDEX('MO Store'!E:E,MATCH($K26,'MO Store'!$A:$A,0)) -> Brittanie Braggs | G26: =INDEX('MO Store'!I:I,MATCH($K26,'MO Store'!$A:$A,0)) -> Regular | H26: AXS0 | I26: DREW RUDH | J26: CE | K26: 222262 | L26: =IF(M26>35,"Yes","No") -> Yes | M26: 40.26 | N26: 0 | O26: 0 | P26: =SUM(N26:O26) -> 0
A27: =INDEX('MO Store'!B:B,MATCH($K27,'MO Store'!$A:$A,0)) -> Houston North East | B27: =INDEX('MO Store'!C:C,MATCH($K27,'MO Store'!$A:$A,0)) -> Midtown | C27: =INDEX('MO Store'!D:D,MATCH($K27,'MO Store'!$A:$A,0)) -> Anthony Galichet | D27: =INDEX('MO Store'!F:F,MATCH($K27,'MO Store'!$A:$A,0)) -> Romio Hamdar | E27: =INDEX('MO Store'!G:G,MATCH($K27,'MO Store'!$A:$A,0)) -> Suhail Ishaq | F27: =INDEX('MO Store'!E:E,MATCH($K27,'MO Store'!$A:$A,0)) -> Brittanie Braggs | G27: =INDEX('MO Store'!I:I,MATCH($K27,'MO Store'!$A:$A,0)) -> Battleship | H27: AXAM | I27: JOSE SANCHEZ | J27: BCE | K27: 176027 | L27: =IF(M27>35,"Yes","No") -> Yes | M27: 42.31 | N27: 0 | O27: 0 | P27: =SUM(N27:O27) -> 0
A28: =INDEX('MO Store'!B:B,MATCH($K28,'MO Store'!$A:$A,0)) -> Houston North East | B28: =INDEX('MO Store'!C:C,MATCH($K28,'MO Store'!$A:$A,0)) -> Rosenberg | C28: =INDEX('MO Store'!D:D,MATCH($K28,'MO Store'!$A:$A,0)) -> Anthony Galichet | D28: =INDEX('MO Store'!F:F,MATCH($K28,'MO Store'!$A:$A,0)) -> Romio Hamdar | E28: =INDEX('MO Store'!G:G,MATCH($K28,'MO Store'!$A:$A,0)) -> Suhail Ishaq | F28: =INDEX('MO Store'!E:E,MATCH($K28,'MO Store'!$A:$A,0)) -> Brittanie Braggs | G28: =INDEX('MO Store'!I:I,MATCH($K28,'MO Store'!$A:$A,0)) -> Focus | H28: AX8O | I28: MODOU SANYANG | J28: BCE | K28: 219200 | L28: =IF(M28>35,"Yes","No") -> Yes | M28: 36.06 | N28: 0 | O28: 0 | P28: =SUM(N28:O28) -> 0
A29: =INDEX('MO Store'!B:B,MATCH($K29,'MO Store'!$A:$A,0)) -> Houston South West | B29: =INDEX('MO Store'!C:C,MATCH($K29,'MO Store'!$A:$A,0)) -> The Grid | C29: =INDEX('MO Store'!D:D,MATCH($K29,'MO Store'!$A:$A,0)) -> Anthony Galichet | D29: =INDEX('MO Store'!F:F,MATCH($K29,'MO Store'!$A:$A,0)) -> Romio Hamdar | E29: =INDEX('MO Store'!G:G,MATCH($K29,'MO Store'!$A:$A,0)) -> Carlos Ayala-Level Up | F29: =INDEX('MO Store'!E:E,MATCH($K29,'MO Store'!$A:$A,0)) -> Brittanie Braggs | G29: =INDEX('MO Store'!I:I,MATCH($K29,'MO Store'!$A:$A,0)) -> Battleship | H29: ARAV | I29: DIEGO VILLALPANDO | J29: BCE | K29: 209858 | L29: =IF(M29>35,"Yes","No") -> Yes | M29: 39.61 | N29: 0 | O29: 0 | P29: =SUM(N29:O29) -> 0
A30: =INDEX('MO Store'!B:B,MATCH($K30,'MO Store'!$A:$A,0)) -> San Antonio/Laredo | B30: =INDEX('MO Store'!C:C,MATCH($K30,'MO Store'!$A:$A,0)) -> San Pedro | C30: =INDEX('MO Store'!D:D,MATCH($K30,'MO Store'!$A:$A,0)) -> Anthony Galichet | D30: =INDEX('MO Store'!F:F,MATCH($K30,'MO Store'!$A:$A,0)) -> Romio Hamdar | E30: =INDEX('MO Store'!G:G,MATCH($K30,'MO Store'!$A:$A,0)) -> Veronica Ramos | F30: =INDEX('MO Store'!E:E,MATCH($K30,'MO Store'!$A:$A,0)) -> Brittanie Braggs | G30: =INDEX('MO Store'!I:I,MATCH($K30,'MO Store'!$A:$A,0)) -> Flagship | H30: AXR9 | I30: NICHOLAS WILMOTH | J30: BSL | K30: 215746 | L30: =IF(M30>35,"Yes","No") -> Yes | M30: 40.17 | N30: 0 | O30: 0 | P30: =SUM(N30:O30) -> 0
A31: =INDEX('MO Store'!B:B,MATCH($K31,'MO Store'!$A:$A,0)) -> Houston South West | B31: =INDEX('MO Store'!C:C,MATCH($K31,'MO Store'!$A:$A,0)) -> Memorial Dr | C31: =INDEX('MO Store'!D:D,MATCH($K31,'MO Store'!$A:$A,0)) -> Anthony Galichet | D31: =INDEX('MO Store'!F:F,MATCH($K31,'MO Store'!$A:$A,0)) -> Romio Hamdar | E31: =INDEX('MO Store'!G:G,MATCH($K31,'MO Store'!$A:$A,0)) -> Carlos Ayala-Level Up | F31: =INDEX('MO Store'!E:E,MATCH($K31,'MO Store'!$A:$A,0)) -> Brittanie Braggs | G31: =INDEX('MO Store'!I:I,MATCH($K31,'MO Store'!$A:$A,0)) -> Regular | H31: A1HT | I31: GUILLERMO ZENTENO GUMUCIO | J31: BCE | K31: 213409 | L31: =IF(M31>35,"Yes","No") -> Yes | M31: 36.43 | N31: 0 | O31: 0 | P31: =SUM(N31:O31) -> 0
A32: =INDEX('MO Store'!B:B,MATCH($K32,'MO Store'!$A:$A,0)) -> San Antonio/Laredo | B32: =INDEX('MO Store'!C:C,MATCH($K32,'MO Store'!$A:$A,0)) -> EAGLE PASS | C32: =INDEX('MO Store'!D:D,MATCH($K32,'MO Store'!$A:$A,0)) -> Anthony Galichet | D32: =INDEX('MO Store'!F:F,MATCH($K32,'MO Store'!$A:$A,0)) -> Romio Hamdar | E32: =INDEX('MO Store'!G:G,MATCH($K32,'MO Store'!$A:$A,0)) -> Veronica Ramos | F32: =INDEX('MO Store'!E:E,MATCH($K32,'MO Store'!$A:$A,0)) -> Brittanie Braggs | G32: =INDEX('MO Store'!I:I,MATCH($K32,'MO Store'!$A:$A,0)) -> Flagship | H32: AR9H | I32: STEPHANIE GONZALEZ | J32: BCE | K32: 207753 | L32: =IF(M32>35,"Yes","No") -> Yes | M32: 35.34 | N32: 0 | O32: 0 | P32: =SUM(N32:O32) -> 0
A33: =INDEX('MO Store'!B:B,MATCH($K33,'MO Store'!$A:$A,0)) -> Houston North East | B33: =INDEX('MO Store'!C:C,MATCH($K33,'MO Store'!$A:$A,0)) -> Richmond (River Park) | C33: =INDEX('MO Store'!D:D,MATCH($K33,'MO Store'!$A:$A,0)) -> Anthony Galichet | D33: =INDEX('MO Store'!F:F,MATCH($K33,'MO Store'!$A:$A,0)) -> Romio Hamdar | E33: =INDEX('MO Store'!G:G,MATCH($K33,'MO Store'!$A:$A,0)) -> Suhail Ishaq | F33: =INDEX('MO Store'!E:E,MATCH($K33,'MO Store'!$A:$A,0)) -> Brittanie Braggs | G33: =INDEX('MO Store'!I:I,MATCH($K33,'MO Store'!$A:$A,0)) -> Regular | H33: AWDG | I33: RAYN KAREDIA | J33: CE | K33: 174110 | L33: =IF(M33>35,"Yes","No") -> Yes | M33: 36.68 | N33: 0 | O33: 0 | P33: =SUM(N33:O33) -> 0
A34: =INDEX('MO Store'!B:B,MATCH($K34,'MO Store'!$A:$A,0)) -> Houston North East | B34: =INDEX('MO Store'!C:C,MATCH($K34,'MO Store'!$A:$A,0)) -> Antoine Town Center | C34: =INDEX('MO Store'!D:D,MATCH($K34,'MO Store'!$A:$A,0)) -> Anthony Galichet | D34: =INDEX('MO Store'!F:F,MATCH($K34,'MO Store'!$A:$A,0)) -> Romio Hamdar | E34: =INDEX('MO Store'!G:G,MATCH($K34,'MO Store'!$A:$A,0)) -> Suhail Ishaq | F34: =INDEX('MO Store'!E:E,MATCH($K34,'MO Store'!$A:$A,0)) -> Brittanie Braggs | G34: =INDEX('MO Store'!I:I,MATCH($K34,'MO Store'!$A:$A,0)) -> Regular | H34: AW17 | I34: VICTORIA MEDINA | J34: BCE | K34: 209865 | L34: =IF(M34>35,"Yes","No") -> Yes | M34: 37.42 | N34: 0 | O34: 0 | P34: =SUM(N34:O34) -> 0
A35: =INDEX('MO Store'!B:B,MATCH($K35,'MO Store'!$A:$A,0)) -> San Antonio/Laredo | B35: =INDEX('MO Store'!C:C,MATCH($K35,'MO Store'!$A:$A,0)) -> Uvalde | C35: =INDEX('MO Store'!D:D,MATCH($K35,'MO Store'!$A:$A,0)) -> Anthony Galichet | D35: =INDEX('MO Store'!F:F,MATCH($K35,'MO Store'!$A:$A,0)) -> Romio Hamdar | E35: =INDEX('MO Store'!G:G,MATCH($K35,'MO Store'!$A:$A,0)) -> Veronica Ramos | F35: =INDEX('MO Store'!E:E,MATCH($K35,'MO Store'!$A:$A,0)) -> Brittanie Braggs | G35: =INDEX('MO Store'!I:I,MATCH($K35,'MO Store'!$A:$A,0)) -> Flagship | H35: AWOG | I35: OSCAR URRABAZO | J35: BCE | K35: 215747 | L35: =IF(M35>35,"Yes","No") -> Yes | M35: 37.52 | N35: 0 | O35: 0 | P35: =SUM(N35:O35) -> 0
A36: =INDEX('MO Store'!B:B,MATCH($K36,'MO Store'!$A:$A,0)) -> San Antonio/Laredo | B36: =INDEX('MO Store'!C:C,MATCH($K36,'MO Store'!$A:$A,0)) -> DEL RIO | C36: =INDEX('MO Store'!D:D,MATCH($K36,'MO Store'!$A:$A,0)) -> Anthony Galichet | D36: =INDEX('MO Store'!F:F,MATCH($K36,'MO Store'!$A:$A,0)) -> Romio Hamdar | E36: =INDEX('MO Store'!G:G,MATCH($K36,'MO Store'!$A:$A,0)) -> Veronica Ramos | F36: =INDEX('MO Store'!E:E,MATCH($K36,'MO Store'!$A:$A,0)) -> Brittanie Braggs | G36: =INDEX('MO Store'!I:I,MATCH($K36,'MO Store'!$A:$A,0)) -> Flagship | H36: AWFC | I36: VALERIE VALDEZ | J36: BCE | K36: 207754 | L36: =IF(M36>35,"Yes","No") -> Yes | M36: 36.28 | N36: 0 | O36: 0 | P36: =SUM(N36:O36) -> 0
A37: =INDEX('MO Store'!B:B,MATCH($K37,'MO Store'!$A:$A,0)) -> Houston East | B37: =INDEX('MO Store'!C:C,MATCH($K37,'MO Store'!$A:$A,0)) -> Fairmont Pkwy | C37: =INDEX('MO Store'!D:D,MATCH($K37,'MO Store'!$A:$A,0)) -> Anthony Galichet | D37: =INDEX('MO Store'!F:F,MATCH($K37,'MO Store'!$A:$A,0)) -> Romio Hamdar | E37: =INDEX('MO Store'!G:G,MATCH($K37,'MO Store'!$A:$A,0)) -> Isreal Gomez- Level Up | F37: =INDEX('MO Store'!E:E,MATCH($K37,'MO Store'!$A:$A,0)) -> Brittanie Braggs | G37: =INDEX('MO Store'!I:I,MATCH($K37,'MO Store'!$A:$A,0)) -> Focus | H37: AVIN | I37: JOSE VALENCIA | J37: BSL | K37: 209869 | L37: =IF(M37>35,"Yes","No") -> Yes | M37: 48.7 | N37: 0 | O37: 0 | P37: =SUM(N37:O37) -> 0
... A100: =INDEX('MO Store'!B:B,MATCH($K100,'MO Store'!$A:$A,0)) -> Austin | B100: =INDEX('MO Store'!C:C,MATCH($K100,'MO Store'!$A:$A,0)) -> Buda Town Center | C100: =INDEX('MO Store'!D:D,MATCH($K100,'MO Store'!$A:$A,0)) -> Anthony Galichet | D100: =INDEX('MO Store'!F:F,MATCH($K100,'MO Store'!$A:$A,0)) -> Romio Hamdar | E100: =INDEX('MO Store'!G:G,MATCH($K100,'MO Store'!$A:$A,0)) -> Austin TM | F100: =INDEX('MO Store'!E:E,MATCH($K100,'MO Store'!$A:$A,0)) -> Brittanie Braggs | G100: =INDEX('MO Store'!I:I,MATCH($K100,'MO Store'!$A:$A,0)) -> Regular | H100: A8KH | I100: AUSTIN KNOX | J100: CE | K100: 176039 | L100: =IF(M100>35,"Yes","No") -> No | M100: 30.83 | N100: 0 | O100: 0 | P100: =SUM(N100:O100) -> 0
A101: =INDEX('MO Store'!B:B,MATCH($K101,'MO Store'!$A:$A,0)) -> Houston North East | B101: =INDEX('MO Store'!C:C,MATCH($K101,'MO Store'!$A:$A,0)) -> Fondren Village | C101: =INDEX('MO Store'!D:D,MATCH($K101,'MO Store'!$A:$A,0)) -> Anthony Galichet | D101: =INDEX('MO Store'!F:F,MATCH($K101,'MO Store'!$A:$A,0)) -> Romio Hamdar | E101: =INDEX('MO Store'!G:G,MATCH($K101,'MO Store'!$A:$A,0)) -> Suhail Ishaq | F101: =INDEX('MO Store'!E:E,MATCH($K101,'MO Store'!$A:$A,0)) -> Brittanie Braggs | G101: Closed | H101: AWC0 | I101: ISRAEL LERMA | J101: BCE | K101: 209863 | L101: =IF(M101>35,"Yes","No") -> No | M101: 32.94 | N101: 0 | O101: 0 | P101: =SUM(N101:O101) -> 0
A102: =INDEX('MO Store'!B:B,MATCH($K102,'MO Store'!$A:$A,0)) -> Arizona | B102: =INDEX('MO Store'!C:C,MATCH($K102,'MO Store'!$A:$A,0)) -> VAL VISTA | C102: =INDEX('MO Store'!D:D,MATCH($K102,'MO Store'!$A:$A,0)) -> Anthony Galichet | D102: =INDEX('MO Store'!F:F,MATCH($K102,'MO Store'!$A:$A,0)) -> No SD | E102: =INDEX('MO Store'!G:G,MATCH($K102,'MO Store'!$A:$A,0)) -> Susu Leong | F102: =INDEX('MO Store'!E:E,MATCH($K102,'MO Store'!$A:$A,0)) -> Brittanie Braggs | G102: =INDEX('MO Store'!I:I,MATCH($K102,'MO Store'!$A:$A,0)) -> Regular | H102: AW6W | I102: RICH LIN | J102: CE | K102: 176995 | L102: =IF(M102>35,"Yes","No") -> No | M102: 18.75 | N102: 0 | O102: 0 | P102: =SUM(N102:O102) -> 0
A103: =INDEX('MO Store'!B:B,MATCH($K103,'MO Store'!$A:$A,0)) -> Arizona | B103: =INDEX('MO Store'!C:C,MATCH($K103,'MO Store'!$A:$A,0)) -> Buffalo Spot | C103: =INDEX('MO Store'!D:D,MATCH($K103,'MO Store'!$A:$A,0)) -> Anthony Galichet | D103: =INDEX('MO Store'!F:F,MATCH($K103,'MO Store'!$A:$A,0)) -> No SD | E103: =INDEX('MO Store'!G:G,MATCH($K103,'MO Store'!$A:$A,0)) -> Susu Leong | F103: =INDEX('MO Store'!E:E,MATCH($K103,'MO Store'!$A:$A,0)) -> Brittanie Braggs | G103: =INDEX('MO Store'!I:I,MATCH($K103,'MO Store'!$A:$A,0)) -> Battleship | H103: AXHO | I103: DEZIREE LOPEZ | J103: BCE | K103: 178109 | L103: =IF(M103>35,"Yes","No") -> No | M103: 29.35 | N103: 0 | O103: 0 | P103: =SUM(N103:O103) -> 0
A104: =INDEX('MO Store'!B:B,MATCH($K104,'MO Store'!$A:$A,0)) -> Arizona | B104: =INDEX('MO Store'!C:C,MATCH($K104,'MO Store'!$A:$A,0)) -> Old Vail Plaza | C104: =INDEX('MO Store'!D:D,MATCH($K104,'MO Store'!$A:$A,0)) -> Anthony Galichet | D104: =INDEX('MO Store'!F:F,MATCH($K104,'MO Store'!$A:$A,0)) -> No SD | E104: =INDEX('MO Store'!G:G,MATCH($K104,'MO Store'!$A:$A,0)) -> Susu Leong | F104: =INDEX('MO Store'!E:E,MATCH($K104,'MO Store'!$A:$A,0)) -> Brittanie Braggs | G104: =INDEX('MO Store'!I:I,MATCH($K104,'MO Store'!$A:$A,0)) -> Regular | H104: AXTK | I104: EDUARDO LOPEZ | J104: HBRSM | K104: 222262 | L104: =IF(M104>35,"Yes","No") -> No | M104: 15.39 | N104: 0 | O104: 0 | P104: =SUM(N104:O104) -> 0
A105: =INDEX('MO Store'!B:B,MATCH($K105,'MO Store'!$A:$A,0)) -> Colorado | B105: =INDEX('MO Store'!C:C,MATCH($K105,'MO Store'!$A:$A,0)) -> Grand View Market Place | C105: =INDEX('MO Store'!D:D,MATCH($K105,'MO Store'!$A:$A,0)) -> Anthony Galichet | D105: =INDEX('MO Store'!F:F,MATCH($K105,'MO Store'!$A:$A,0)) -> Romio Hamdar | E105: =INDEX('MO Store'!G:G,MATCH($K105,'MO Store'!$A:$A,0)) -> Colorado Market - No TM | F105: =INDEX('MO Store'!E:E,MATCH($K105,'MO Store'!$A:$A,0)) -> Brittanie Braggs | G105: =INDEX('MO Store'!I:I,MATCH($K105,'MO Store'!$A:$A,0)) -> Regular | H105: AXLJ | I105: LORENA LOPEZ | J105: BCE | K105: 210924 | L105: =IF(M105>35,"Yes","No") -> No | M105: 16.92 | N105: 0 | O105: 0 | P105: =SUM(N105:O105) -> 0
A106: =INDEX('MO Store'!B:B,MATCH($K106,'MO Store'!$A:$A,0)) -> North Carolina | B106: =INDEX('MO Store'!C:C,MATCH($K106,'MO Store'!$A:$A,0)) -> Winterville NC | C106: =INDEX('MO Store'!D:D,MATCH($K106,'MO Store'!$A:$A,0)) -> Anthony Galichet | D106: =INDEX('MO Store'!F:F,MATCH($K106,'MO Store'!$A:$A,0)) -> No SD | E106: =INDEX('MO Store'!G:G,MATCH($K106,'MO Store'!$A:$A,0)) -> North Carolina Market - No TM | F106: =INDEX('MO Store'!E:E,MATCH($K106,'MO Store'!$A:$A,0)) -> Brittanie Braggs | G106: =INDEX('MO Store'!I:I,MATCH($K106,'MO Store'!$A:$A,0)) -> Regular | H106: AX8B | I106: NATALIE LUCKADOO | J106: CE | K106: 177547 | L106: =IF(M106>35,"Yes","No") -> No | M106: 23.68 | N106: 0 | O106: 0 | P106: =SUM(N106:O106) -> 0
A107: =INDEX('MO Store'!B:B,MATCH($K107,'MO Store'!$A:$A,0)) -> San Antonio/Laredo | B107: =INDEX('MO Store'!C:C,MATCH($K107,'MO Store'!$A:$A,0)) -> Uvalde | C107: =INDEX('MO Store'!D:D,MATCH($K107,'MO Store'!$A:$A,0)) -> Anthony Galichet | D107: =INDEX('MO Store'!F:F,MATCH($K107,'MO Store'!$A:$A,0)) -> Romio Hamdar | E107: =INDEX('MO Store'!G:G,MATCH($K107,'MO Store'!$A:$A,0)) -> Veronica Ramos | F107: =INDEX('MO Store'!E:E,MATCH($K107,'MO Store'!$A:$A,0)) -> Brittanie Braggs | G107: =INDEX('MO Store'!I:I,MATCH($K107,'MO Store'!$A:$A,0)) -> Flagship | H107: AWAG | I107: BLANCA LUEVANOS | J107: BCE | K107: 215747 | L107: =IF(M107>35,"Yes","No") -> No | M107: 30.72 | N107: 0 | O107: 0 | P107: =SUM(N107:O107) -> 0
A108: =INDEX('MO Store'!B:B,MATCH($K108,'MO Store'!$A:$A,0)) -> Houston South West | B108: =INDEX('MO Store'!C:C,MATCH($K108,'MO Store'!$A:$A,0)) -> Rice Ave | C108: =INDEX('MO Store'!D:D,MATCH($K108,'MO Store'!$A:$A,0)) -> Anthony Galichet | D108: =INDEX('MO Store'!F:F,MATCH($K108,'MO Store'!$A:$A,0)) -> Romio Hamdar | E108: =INDEX('MO Store'!G:G,MATCH($K108,'MO Store'!$A:$A,0)) -> Carlos Ayala-Level Up | F108: =INDEX('MO Store'!E:E,MATCH($K108,'MO Store'!$A:$A,0)) -> Brittanie Braggs | G108: =INDEX('MO Store'!I:I,MATCH($K108,'MO Store'!$A:$A,0)) -> Regular | H108: AX78 | I108: DULCE MACEDO | J108: BCE | K108: 174112 | L108: =IF(M108>35,"Yes","No") -> No | M108: 26.31 | N108: 0 | O108: 0 | P108: =SUM(N108:O108) -> 0
A109: =INDEX('MO Store'!B:B,MATCH($K109,'MO Store'!$A:$A,0)) -> San Antonio/Laredo | B109: =INDEX('MO Store'!C:C,MATCH($K109,'MO Store'!$A:$A,0)) -> LAREDO PLANTATION CENTRE | C109: =INDEX('MO Store'!D:D,MATCH($K109,'MO Store'!$A:$A,0)) -> Anthony Galichet | D109: =INDEX('MO Store'!F:F,MATCH($K109,'MO Store'!$A:$A,0)) -> Romio Hamdar | E109: =INDEX('MO Store'!G:G,MATCH($K109,'MO Store'!$A:$A,0)) -> Veronica Ramos | F109: =INDEX('MO Store'!E:E,MATCH($K109,'MO Store'!$A:$A,0)) -> Brittanie Braggs | G109: =INDEX('MO Store'!I:I,MATCH($K109,'MO Store'!$A:$A,0)) -> Flagship | H109: AWWO | I109: STEPHANIE MACIAS | J109: BCE | K109: 207752 | L109: =IF(M109>35,"Yes","No") -> No | M109: 31.58 | N109: 0 | O109: 0 | P109: =SUM(N109:O109) -> 0
A110: =INDEX('MO Store'!B:B,MATCH($K110,'MO Store'!$A:$A,0)) -> Arizona | B110: =INDEX('MO Store'!C:C,MATCH($K110,'MO Store'!$A:$A,0)) -> Bethany Home | C110: =INDEX('MO Store'!D:D,MATCH($K110,'MO Store'!$A:$A,0)) -> Anthony Galichet | D110: =INDEX('MO Store'!F:F,MATCH($K110,'MO Store'!$A:$A,0)) -> No SD | E110: =INDEX('MO Store'!G:G,MATCH($K110,'MO Store'!$A:$A,0)) -> Susu Leong | F110: =INDEX('MO Store'!E:E,MATCH($K110,'MO Store'!$A:$A,0)) -> Brittanie Braggs | G110: =INDEX('MO Store'!I:I,MATCH($K110,'MO Store'!$A:$A,0)) -> Regular | H110: AX6A | I110: JOHNATHAN MARCHISIO BAER | J110: CE | K110: 216514 | L110: =IF(M110>35,"Yes","No") -> No | M110: 30.64 | N110: 0 | O110: 0 | P110: =SUM(N110:O110) -> 0
A111: =INDEX('MO Store'!B:B,MATCH($K111,'MO Store'!$A:$A,0)) -> San Antonio/Laredo | B111: =INDEX('MO Store'!C:C,MATCH($K111,'MO Store'!$A:$A,0)) -> EAGLE PASS | C111: =INDEX('MO Store'!D:D,MATCH($K111,'MO Store'!$A:$A,0)) -> Anthony Galichet | D111: =INDEX('MO Store'!F:F,MATCH($K111,'MO Store'!$A:$A,0)) -> Romio Hamdar | E111: =INDEX('MO Store'!G:G,MATCH($K111,'MO Store'!$A:$A,0)) -> Veronica Ramos | F111: =INDEX('MO Store'!E:E,MATCH($K111,'MO Store'!$A:$A,0)) -> Brittanie Braggs | G111: =INDEX('MO Store'!I:I,MATCH($K111,'MO Store'!$A:$A,0)) -> Flagship | H111: AW2W | I111: DAVID MARTINEZ | J111: BSL | K111: 207753 | L111: =IF(M111>35,"Yes","No") -> No | M111: 32.05 | N111: 0 | O111: 0 | P111: =SUM(N111:O111) -> 0
...

Sheet Week Wise OT Hours
